# JavaScript Promise: Resolve, Reject, 그리고 에러 핸들링 정리

JavaScript의 **Promise**는 비동기 작업을 처리하기 위한 객체로, 작업의 성공 또는 실패 상태를 나타냅니다. Promise는 **`resolve`**, **`reject`** 메서드를 통해 작업의 결과를 전달하며, 에러가 발생할 경우 이를 처리하기 위한 **에러 핸들링** 메커니즘을 제공합니다.

---

## 📖 Resolve와 Reject란?

### **1. Resolve**
- **`resolve`** 는 Promise가 성공적으로 완료되었음을 나타내며, 결과 값을 전달합니다.
- Promise가 `resolve`되면 상태가 **Fulfilled(이행됨)** 으로 변경됩니다.

#### 예제:
```
const promise = new Promise((resolve, reject) => {
    resolve("Task completed successfully!");
});

promise.then(result => console.log(result)); // "Task completed successfully!"
```

---

### **2. Reject**
- **`reject`** 는 Promise가 실패했음을 나타내며, 에러나 실패 이유를 전달합니다.
- Promise가 `reject`되면 상태가 **Rejected(거부됨)** 으로 변경됩니다.

#### 예제:
```
const promise = new Promise((resolve, reject) => {
    reject(new Error("Task failed!"));
});

promise.catch(error => console.error(error)); // Error: Task failed!
```

---

## 📂 Resolve와 Reject의 동작 원리

1. **상태 변경**
   - Promise는 초기 상태인 `Pending(대기)`에서 시작합니다.
   - `resolve()` 또는 `reject()`가 호출되면 상태가 각각 `Fulfilled(이행됨)` 또는 `Rejected(거부됨)`으로 변경됩니다.
   - 한 번 상태가 변경되면 다시 변경되지 않습니다.

#### 예제:
```
const promise = new Promise((resolve, reject) => {
    resolve("First resolve");
    reject("This will be ignored"); // 무시됨
});

promise.then(result => console.log(result)); // "First resolve"
```

2. **비동기 작업 처리**
   - Promise는 비동기 작업의 결과를 처리하는 데 사용됩니다.
   - 네트워크 요청, 타이머 등에서 자주 사용됩니다.

---

## 📂 에러 핸들링

### **1. 기본 에러 핸들링: `.catch()`**

- `.catch()`는 Promise 체인에서 발생한 에러를 처리합니다.
- 체인의 어느 단계에서든 에러가 발생하면 `.catch()`로 제어 흐름이 이동합니다.

#### 예제:
```
const promise = new Promise((resolve, reject) => {
    reject(new Error("Something went wrong!"));
});

promise.catch(error => console.error(error)); // Error: Something went wrong!
```

---

### **2. 체인 내 에러 핸들링**

- `.catch()`는 체인의 마지막에 추가하여 모든 에러를 처리할 수 있습니다.

#### 예제:
```
new Promise((resolve, reject) => {
    throw new Error("Error in the first step!");
})
.then(result => console.log(result)) // 실행되지 않음
.catch(error => console.error(error)); // "Error in the first step!"
```

---

### **3. 여러 단계의 에러 핸들링**

- 체인의 각 단계에서 개별적으로 에러를 처리할 수 있습니다.

#### 예제:
```
new Promise((resolve, reject) => {
    resolve("Step 1 success");
})
.then(result => {
    console.log(result); // "Step 1 success"
    throw new Error("Error in Step 2");
})
.catch(error => {
    console.error("Caught an error:", error); // "Caught an error: Error in Step 2"
});
```

---

### **4. 네트워크 요청 예제**

#### 성공적인 요청:
```
function fetchData(url) {
    return new Promise((resolve, reject) => {
        const xhr = new XMLHttpRequest();
        xhr.open("GET", url);
        xhr.onload = () => {
            if (xhr.status === 200) {
                resolve(xhr.response);
            } else {
                reject(new Error(`Request failed with status ${xhr.status}`));
            }
        };
        xhr.onerror = () => reject(new Error("Network error"));
        xhr.send();
    });
}

fetchData("https://jsonplaceholder.typicode.com/posts/1")
    .then(data => console.log(JSON.parse(data)))
    .catch(error => console.error(error));
```

#### 실패한 요청:
```
fetchData("https://invalid-url")
    .then(data => console.log(data))
    .catch(error => console.error("Error:", error));
// 출력: Error: Network error
```

---

## 📂 Resolve와 Reject 활용 사례

### **1. 성공과 실패 분기 처리**
Promise 내부에서 조건에 따라 `resolve` 또는 `reject`를 호출합니다.

#### 예제:
```
function checkNumber(num) {
    return new Promise((resolve, reject) => {
        if (num > 0) {
            resolve(`${num} is positive`);
        } else {
            reject(`${num} is not positive`);
        }
    });
}

checkNumber(5)
    .then(result => console.log(result)) // "5 is positive"
    .catch(error => console.error(error)); // 실행되지 않음
```

---

### **2. `Promise.reject()`와 `Promise.resolve()`**

- `Promise.reject(reason)`와 `Promise.resolve(value)`는 각각 즉시 거부된 또는 이행된 Promise를 반환합니다.

#### 예제:
```
Promise.resolve("Success").then(result => console.log(result)); // "Success"

Promise.reject(new Error("Failure"))
    .catch(error => console.error(error)); // Error: Failure
```

---

## 📂 에러 전파와 복구

### **1. 에러 전파**
- 체인 내에서 발생한 에러는 다음 `.catch()`로 전파됩니다.

#### 예제:
```
new Promise((resolve, reject) => {
    throw new Error("Something went wrong!");
})
.then(() => console.log("This will not run"))
.catch(error => console.error(error)) // "Something went wrong!"
.then(() => console.log("This will run after catch")); // 실행됨
```

---

### **2. 에러 복구**
- `.catch()`에서 새로운 값을 반환하면 체인이 정상적으로 이어집니다.

#### 예제:
```
new Promise((resolve, reject) => {
    throw new Error("Initial error");
})
.catch(error => {
    console.error(error);
    return "Recovered";
})
.then(result => console.log(result)); // "Recovered"
```

---

## ✨ 요약

| 메서드              | 설명                                                                 | 예제                                      |
|---------------------|----------------------------------------------------------------------|------------------------------------------|
| `resolve(value)`     | 작업이 성공했음을 나타내며 결과값을 전달                              | `resolve('Success') → Fulfilled`         |
| `reject(reason)`     | 작업이 실패했음을 나타내며 실패 이유를 전달                           | `reject('Error') → Rejected`             |
| `.then()`           | 이행된 상태일 때 실행될 콜백 등록                                     | `.then(result => {...})`                 |
| `.catch()`          | 거부된 상태일 때 실행될 콜백 등록                                     | `.catch(error => {...})`                 |
| `.finally()`        | 성공/실패 여부와 상관없이 항상 실행                                   | `.finally(() => {...})`                  |

---
